[2025-07-12T14:16:14.526+0000] {taskinstance.py:1956} INFO - Dependencies all met for dep_context=non-requeueable deps ti=<TaskInstance: flight_data_quality_check.check_data_validity manual__2025-07-12T14:16:13.962857+00:00 [queued]>
[2025-07-12T14:16:14.530+0000] {taskinstance.py:1956} INFO - Dependencies all met for dep_context=requeueable deps ti=<TaskInstance: flight_data_quality_check.check_data_validity manual__2025-07-12T14:16:13.962857+00:00 [queued]>
[2025-07-12T14:16:14.530+0000] {taskinstance.py:2170} INFO - Starting attempt 1 of 2
[2025-07-12T14:16:14.537+0000] {taskinstance.py:2191} INFO - Executing <Task(PythonOperator): check_data_validity> on 2025-07-12 14:16:13.962857+00:00
[2025-07-12T14:16:14.542+0000] {standard_task_runner.py:60} INFO - Started process 342 to run task
[2025-07-12T14:16:14.547+0000] {standard_task_runner.py:87} INFO - Running: ['***', 'tasks', 'run', 'flight_data_quality_check', 'check_data_validity', 'manual__2025-07-12T14:16:13.962857+00:00', '--job-id', '33', '--raw', '--subdir', 'DAGS_FOLDER/flight_data_quality.py', '--cfg-path', '/tmp/tmp5bfko4xx']
[2025-07-12T14:16:14.548+0000] {standard_task_runner.py:88} INFO - Job 33: Subtask check_data_validity
[2025-07-12T14:16:14.583+0000] {task_command.py:423} INFO - Running <TaskInstance: flight_data_quality_check.check_data_validity manual__2025-07-12T14:16:13.962857+00:00 [running]> on host 81a20f36e34f
[2025-07-12T14:16:14.783+0000] {taskinstance.py:2480} INFO - Exporting env vars: AIRFLOW_CTX_DAG_OWNER='data_engineer' AIRFLOW_CTX_DAG_ID='flight_data_quality_check' AIRFLOW_CTX_TASK_ID='check_data_validity' AIRFLOW_CTX_EXECUTION_DATE='2025-07-12T14:16:13.962857+00:00' AIRFLOW_CTX_TRY_NUMBER='1' AIRFLOW_CTX_DAG_RUN_ID='manual__2025-07-12T14:16:13.962857+00:00'
[2025-07-12T14:16:14.790+0000] {base.py:83} INFO - Using connection ID 'postgres_default' for task execution.
[2025-07-12T14:16:14.792+0000] {logging_mixin.py:188} INFO - Error checking data validity: connection to server at "postgres" (172.24.0.2), port 5432 failed: FATAL:  password authentication failed for user "postgres"
[2025-07-12T14:16:14.792+0000] {taskinstance.py:2698} ERROR - Task failed with exception
Traceback (most recent call last):
  File "/home/airflow/.local/lib/python3.8/site-packages/airflow/models/taskinstance.py", line 433, in _execute_task
    result = execute_callable(context=context, **execute_callable_kwargs)
  File "/home/airflow/.local/lib/python3.8/site-packages/airflow/operators/python.py", line 199, in execute
    return_value = self.execute_callable()
  File "/home/airflow/.local/lib/python3.8/site-packages/airflow/operators/python.py", line 216, in execute_callable
    return self.python_callable(*self.op_args, **self.op_kwargs)
  File "/opt/airflow/dags/flight_data_quality.py", line 119, in check_data_validity
    duplicates = postgres_hook.get_records(duplicate_query)
  File "/home/airflow/.local/lib/python3.8/site-packages/airflow/providers/common/sql/hooks/sql.py", line 261, in get_records
    return self.run(sql=sql, parameters=parameters, handler=fetch_all_handler)
  File "/home/airflow/.local/lib/python3.8/site-packages/airflow/providers/common/sql/hooks/sql.py", line 391, in run
    with closing(self.get_conn()) as conn:
  File "/home/airflow/.local/lib/python3.8/site-packages/airflow/providers/postgres/hooks/postgres.py", line 158, in get_conn
    self.conn = psycopg2.connect(**conn_args)
  File "/home/airflow/.local/lib/python3.8/site-packages/psycopg2/__init__.py", line 122, in connect
    conn = _connect(dsn, connection_factory=connection_factory, **kwasync)
psycopg2.OperationalError: connection to server at "postgres" (172.24.0.2), port 5432 failed: FATAL:  password authentication failed for user "postgres"

[2025-07-12T14:16:14.797+0000] {taskinstance.py:1138} INFO - Marking task as UP_FOR_RETRY. dag_id=flight_data_quality_check, task_id=check_data_validity, execution_date=20250712T141613, start_date=20250712T141614, end_date=20250712T141614
[2025-07-12T14:16:14.802+0000] {standard_task_runner.py:107} ERROR - Failed to execute job 33 for task check_data_validity (connection to server at "postgres" (172.24.0.2), port 5432 failed: FATAL:  password authentication failed for user "postgres"
; 342)
[2025-07-12T14:16:14.811+0000] {local_task_job_runner.py:234} INFO - Task exited with return code 1
[2025-07-12T14:16:14.827+0000] {taskinstance.py:3280} INFO - 0 downstream tasks scheduled from follow-on schedule check
