[2025-07-12T15:30:07.904+0000] {taskinstance.py:1956} INFO - Dependencies all met for dep_context=non-requeueable deps ti=<TaskInstance: realtime_global_flight_data.merge_and_transform_data scheduled__2025-07-12T15:00:00+00:00 [queued]>
[2025-07-12T15:30:07.907+0000] {taskinstance.py:1956} INFO - Dependencies all met for dep_context=requeueable deps ti=<TaskInstance: realtime_global_flight_data.merge_and_transform_data scheduled__2025-07-12T15:00:00+00:00 [queued]>
[2025-07-12T15:30:07.907+0000] {taskinstance.py:2170} INFO - Starting attempt 1 of 3
[2025-07-12T15:30:07.912+0000] {taskinstance.py:2191} INFO - Executing <Task(PythonOperator): merge_and_transform_data> on 2025-07-12 15:00:00+00:00
[2025-07-12T15:30:07.914+0000] {standard_task_runner.py:60} INFO - Started process 1507 to run task
[2025-07-12T15:30:07.916+0000] {standard_task_runner.py:87} INFO - Running: ['***', 'tasks', 'run', 'realtime_global_flight_data', 'merge_and_transform_data', 'scheduled__2025-07-12T15:00:00+00:00', '--job-id', '101', '--raw', '--subdir', 'DAGS_FOLDER/realtime_global_flight_data.py', '--cfg-path', '/tmp/tmpj88wemit']
[2025-07-12T15:30:07.917+0000] {standard_task_runner.py:88} INFO - Job 101: Subtask merge_and_transform_data
[2025-07-12T15:30:07.935+0000] {task_command.py:423} INFO - Running <TaskInstance: realtime_global_flight_data.merge_and_transform_data scheduled__2025-07-12T15:00:00+00:00 [running]> on host f1b3ce86e5d1
[2025-07-12T15:30:08.024+0000] {taskinstance.py:2480} INFO - Exporting env vars: AIRFLOW_CTX_DAG_OWNER='data_engineer' AIRFLOW_CTX_DAG_ID='realtime_global_flight_data' AIRFLOW_CTX_TASK_ID='merge_and_transform_data' AIRFLOW_CTX_EXECUTION_DATE='2025-07-12T15:00:00+00:00' AIRFLOW_CTX_TRY_NUMBER='1' AIRFLOW_CTX_DAG_RUN_ID='scheduled__2025-07-12T15:00:00+00:00'
[2025-07-12T15:30:08.024+0000] {logging_mixin.py:188} INFO - üîÑ Merging and transforming data from all sources...
[2025-07-12T15:30:08.041+0000] {logging_mixin.py:188} INFO - ‚úÖ Loaded 11820 records from opensky
[2025-07-12T15:30:08.041+0000] {logging_mixin.py:188} INFO - ‚ùå Error reading aviationstack data: No columns to parse from file
[2025-07-12T15:30:08.042+0000] {logging_mixin.py:188} INFO - ‚ùå Error reading airlabs data: No columns to parse from file
[2025-07-12T15:30:08.049+0000] {logging_mixin.py:188} INFO - üîÑ Removed 0 duplicate flights
[2025-07-12T15:30:08.158+0000] {logging_mixin.py:188} INFO - ‚ùå Error merging data: 'airline'
[2025-07-12T15:30:08.158+0000] {taskinstance.py:2698} ERROR - Task failed with exception
Traceback (most recent call last):
  File "/home/airflow/.local/lib/python3.8/site-packages/pandas/core/indexes/base.py", line 3802, in get_loc
    return self._engine.get_loc(casted_key)
  File "pandas/_libs/index.pyx", line 138, in pandas._libs.index.IndexEngine.get_loc
  File "pandas/_libs/index.pyx", line 165, in pandas._libs.index.IndexEngine.get_loc
  File "pandas/_libs/hashtable_class_helper.pxi", line 5745, in pandas._libs.hashtable.PyObjectHashTable.get_item
  File "pandas/_libs/hashtable_class_helper.pxi", line 5753, in pandas._libs.hashtable.PyObjectHashTable.get_item
KeyError: 'airline'

The above exception was the direct cause of the following exception:

Traceback (most recent call last):
  File "/home/airflow/.local/lib/python3.8/site-packages/airflow/models/taskinstance.py", line 433, in _execute_task
    result = execute_callable(context=context, **execute_callable_kwargs)
  File "/home/airflow/.local/lib/python3.8/site-packages/airflow/operators/python.py", line 199, in execute
    return_value = self.execute_callable()
  File "/home/airflow/.local/lib/python3.8/site-packages/airflow/operators/python.py", line 216, in execute_callable
    return self.python_callable(*self.op_args, **self.op_kwargs)
  File "/opt/airflow/dags/realtime_global_flight_data.py", line 388, in merge_and_transform_data
    summary = generate_data_summary(merged_df)
  File "/opt/airflow/dags/realtime_global_flight_data.py", line 465, in generate_data_summary
    'airlines': len(df['airline'].unique()),
  File "/home/airflow/.local/lib/python3.8/site-packages/pandas/core/frame.py", line 3807, in __getitem__
    indexer = self.columns.get_loc(key)
  File "/home/airflow/.local/lib/python3.8/site-packages/pandas/core/indexes/base.py", line 3804, in get_loc
    raise KeyError(key) from err
KeyError: 'airline'
[2025-07-12T15:30:08.163+0000] {taskinstance.py:1138} INFO - Marking task as UP_FOR_RETRY. dag_id=realtime_global_flight_data, task_id=merge_and_transform_data, execution_date=20250712T150000, start_date=20250712T153007, end_date=20250712T153008
[2025-07-12T15:30:08.167+0000] {standard_task_runner.py:107} ERROR - Failed to execute job 101 for task merge_and_transform_data ('airline'; 1507)
[2025-07-12T15:30:08.194+0000] {local_task_job_runner.py:234} INFO - Task exited with return code 1
[2025-07-12T15:30:08.261+0000] {taskinstance.py:3280} INFO - 0 downstream tasks scheduled from follow-on schedule check
