[2025-07-12T13:48:32.918+0000] {taskinstance.py:1956} INFO - Dependencies all met for dep_context=non-requeueable deps ti=<TaskInstance: flight_data_quality_check.check_data_freshness scheduled__2025-07-12T00:00:00+00:00 [queued]>
[2025-07-12T13:48:32.921+0000] {taskinstance.py:1956} INFO - Dependencies all met for dep_context=requeueable deps ti=<TaskInstance: flight_data_quality_check.check_data_freshness scheduled__2025-07-12T00:00:00+00:00 [queued]>
[2025-07-12T13:48:32.921+0000] {taskinstance.py:2170} INFO - Starting attempt 2 of 2
[2025-07-12T13:48:32.927+0000] {taskinstance.py:2191} INFO - Executing <Task(PythonOperator): check_data_freshness> on 2025-07-12 00:00:00+00:00
[2025-07-12T13:48:32.929+0000] {standard_task_runner.py:60} INFO - Started process 491 to run task
[2025-07-12T13:48:32.931+0000] {standard_task_runner.py:87} INFO - Running: ['***', 'tasks', 'run', 'flight_data_quality_check', 'check_data_freshness', 'scheduled__2025-07-12T00:00:00+00:00', '--job-id', '24', '--raw', '--subdir', 'DAGS_FOLDER/flight_data_quality.py', '--cfg-path', '/tmp/tmpc9vwfx0t']
[2025-07-12T13:48:32.932+0000] {standard_task_runner.py:88} INFO - Job 24: Subtask check_data_freshness
[2025-07-12T13:48:32.951+0000] {task_command.py:423} INFO - Running <TaskInstance: flight_data_quality_check.check_data_freshness scheduled__2025-07-12T00:00:00+00:00 [running]> on host d712b9c489aa
[2025-07-12T13:48:33.091+0000] {taskinstance.py:2480} INFO - Exporting env vars: AIRFLOW_CTX_DAG_OWNER='data_engineer' AIRFLOW_CTX_DAG_ID='flight_data_quality_check' AIRFLOW_CTX_TASK_ID='check_data_freshness' AIRFLOW_CTX_EXECUTION_DATE='2025-07-12T00:00:00+00:00' AIRFLOW_CTX_TRY_NUMBER='2' AIRFLOW_CTX_DAG_RUN_ID='scheduled__2025-07-12T00:00:00+00:00'
[2025-07-12T13:48:33.095+0000] {base.py:83} INFO - Using connection ID 'postgres_default' for task execution.
[2025-07-12T13:48:33.097+0000] {logging_mixin.py:188} INFO - Error checking data freshness: connection to server at "postgres" (172.20.0.2), port 5432 failed: FATAL:  password authentication failed for user "postgres"
[2025-07-12T13:48:33.097+0000] {taskinstance.py:2698} ERROR - Task failed with exception
Traceback (most recent call last):
  File "/home/airflow/.local/lib/python3.8/site-packages/airflow/models/taskinstance.py", line 433, in _execute_task
    result = execute_callable(context=context, **execute_callable_kwargs)
  File "/home/airflow/.local/lib/python3.8/site-packages/airflow/operators/python.py", line 199, in execute
    return_value = self.execute_callable()
  File "/home/airflow/.local/lib/python3.8/site-packages/airflow/operators/python.py", line 216, in execute_callable
    return self.python_callable(*self.op_args, **self.op_kwargs)
  File "/opt/airflow/dags/flight_data_quality.py", line 36, in check_data_freshness
    airports_result = postgres_hook.get_first(airports_query)
  File "/home/airflow/.local/lib/python3.8/site-packages/airflow/providers/common/sql/hooks/sql.py", line 270, in get_first
    return self.run(sql=sql, parameters=parameters, handler=fetch_one_handler)
  File "/home/airflow/.local/lib/python3.8/site-packages/airflow/providers/common/sql/hooks/sql.py", line 391, in run
    with closing(self.get_conn()) as conn:
  File "/home/airflow/.local/lib/python3.8/site-packages/airflow/providers/postgres/hooks/postgres.py", line 158, in get_conn
    self.conn = psycopg2.connect(**conn_args)
  File "/home/airflow/.local/lib/python3.8/site-packages/psycopg2/__init__.py", line 122, in connect
    conn = _connect(dsn, connection_factory=connection_factory, **kwasync)
psycopg2.OperationalError: connection to server at "postgres" (172.20.0.2), port 5432 failed: FATAL:  password authentication failed for user "postgres"

[2025-07-12T13:48:33.101+0000] {taskinstance.py:1138} INFO - Marking task as FAILED. dag_id=flight_data_quality_check, task_id=check_data_freshness, execution_date=20250712T000000, start_date=20250712T134832, end_date=20250712T134833
[2025-07-12T13:48:33.105+0000] {standard_task_runner.py:107} ERROR - Failed to execute job 24 for task check_data_freshness (connection to server at "postgres" (172.20.0.2), port 5432 failed: FATAL:  password authentication failed for user "postgres"
; 491)
[2025-07-12T13:48:33.110+0000] {local_task_job_runner.py:234} INFO - Task exited with return code 1
[2025-07-12T13:48:33.131+0000] {taskinstance.py:3280} INFO - 0 downstream tasks scheduled from follow-on schedule check
