[2025-07-12T13:48:24.096+0000] {taskinstance.py:1956} INFO - Dependencies all met for dep_context=non-requeueable deps ti=<TaskInstance: flight_data_etl.load_to_database manual__2025-07-12T13:48:19+00:00 [queued]>
[2025-07-12T13:48:24.099+0000] {taskinstance.py:1956} INFO - Dependencies all met for dep_context=requeueable deps ti=<TaskInstance: flight_data_etl.load_to_database manual__2025-07-12T13:48:19+00:00 [queued]>
[2025-07-12T13:48:24.099+0000] {taskinstance.py:2170} INFO - Starting attempt 1 of 2
[2025-07-12T13:48:24.104+0000] {taskinstance.py:2191} INFO - Executing <Task(PythonOperator): load_to_database> on 2025-07-12 13:48:19+00:00
[2025-07-12T13:48:24.105+0000] {standard_task_runner.py:60} INFO - Started process 484 to run task
[2025-07-12T13:48:24.107+0000] {standard_task_runner.py:87} INFO - Running: ['***', 'tasks', 'run', 'flight_data_etl', 'load_to_database', 'manual__2025-07-12T13:48:19+00:00', '--job-id', '21', '--raw', '--subdir', 'DAGS_FOLDER/flight_data_etl.py', '--cfg-path', '/tmp/tmper6ic61s']
[2025-07-12T13:48:24.107+0000] {standard_task_runner.py:88} INFO - Job 21: Subtask load_to_database
[2025-07-12T13:48:24.123+0000] {task_command.py:423} INFO - Running <TaskInstance: flight_data_etl.load_to_database manual__2025-07-12T13:48:19+00:00 [running]> on host d712b9c489aa
[2025-07-12T13:48:24.218+0000] {taskinstance.py:2480} INFO - Exporting env vars: AIRFLOW_CTX_DAG_OWNER='data_engineer' AIRFLOW_CTX_DAG_ID='flight_data_etl' AIRFLOW_CTX_TASK_ID='load_to_database' AIRFLOW_CTX_EXECUTION_DATE='2025-07-12T13:48:19+00:00' AIRFLOW_CTX_TRY_NUMBER='1' AIRFLOW_CTX_DAG_RUN_ID='manual__2025-07-12T13:48:19+00:00'
[2025-07-12T13:48:24.223+0000] {base.py:83} INFO - Using connection ID 'postgres_default' for task execution.
[2025-07-12T13:48:24.226+0000] {logging_mixin.py:188} INFO - Error loading airport data: (psycopg2.OperationalError) connection to server at "postgres" (172.20.0.2), port 5432 failed: FATAL:  password authentication failed for user "postgres"

(Background on this error at: https://sqlalche.me/e/14/e3q8)
[2025-07-12T13:48:24.231+0000] {base.py:83} INFO - Using connection ID 'postgres_default' for task execution.
[2025-07-12T13:48:24.232+0000] {logging_mixin.py:188} INFO - Error loading schedule data: (psycopg2.OperationalError) connection to server at "postgres" (172.20.0.2), port 5432 failed: FATAL:  password authentication failed for user "postgres"

(Background on this error at: https://sqlalche.me/e/14/e3q8)
[2025-07-12T13:48:24.249+0000] {base.py:83} INFO - Using connection ID 'postgres_default' for task execution.
[2025-07-12T13:48:24.251+0000] {logging_mixin.py:188} INFO - Error loading real-time data: (psycopg2.OperationalError) connection to server at "postgres" (172.20.0.2), port 5432 failed: FATAL:  password authentication failed for user "postgres"

(Background on this error at: https://sqlalche.me/e/14/e3q8)
[2025-07-12T13:48:24.251+0000] {python.py:201} INFO - Done. Returned value was: None
[2025-07-12T13:48:24.254+0000] {taskinstance.py:1138} INFO - Marking task as SUCCESS. dag_id=flight_data_etl, task_id=load_to_database, execution_date=20250712T134819, start_date=20250712T134824, end_date=20250712T134824
[2025-07-12T13:48:24.289+0000] {local_task_job_runner.py:234} INFO - Task exited with return code 0
[2025-07-12T13:48:24.296+0000] {taskinstance.py:3280} INFO - 0 downstream tasks scheduled from follow-on schedule check
